import React from 'react';
import { render, screen } from '@testing-library/react';
import ErrorBoundary from '@/components/error-boundary/ErrorBoundary';

// Helper component that throws an error
const ThrowError = ({ shouldThrow = true }) => {
  if (shouldThrow) {
    throw new Error('Test error');
  }
  return <div>No error</div>;
};

describe('ErrorBoundary', () => {
  // Prevent console.error from cluttering the test output
  const originalConsoleError = console.error;
  beforeAll(() => {
    console.error = jest.fn();
  });

  afterAll(() => {
    console.error = originalConsoleError;
  });

  it('renders children when there is no error', () => {
    render(
      <ErrorBoundary>
        <div>Test content</div>
      </ErrorBoundary>
    );

    expect(screen.getByText('Test content')).toBeInTheDocument();
  });

  it('renders default error UI when child throws', () => {
    render(
      <ErrorBoundary>
        <ThrowError />
      </ErrorBoundary>
    );

    expect(screen.getByText('Something went wrong')).toBeInTheDocument();
  });

  it('renders custom fallback when provided and child throws', () => {
    const fallback = <div>Custom error message</div>;
    render(
      <ErrorBoundary fallback={fallback}>
        <ThrowError />
      </ErrorBoundary>
    );

    expect(screen.getByText('Custom error message')).toBeInTheDocument();
  });

  it('calls console.error when error occurs', () => {
    render(
      <ErrorBoundary>
        <ThrowError />
      </ErrorBoundary>
    );

    expect(console.error).toHaveBeenCalled();
  });
});
